[2023-03-29 23:36:04,189] {taskinstance.py:1159} INFO - Dependencies all met for <TaskInstance: weather_dag.extraction_weather_data manual__2023-03-30T02:36:00.079532+00:00 [queued]>
[2023-03-29 23:36:04,192] {taskinstance.py:1159} INFO - Dependencies all met for <TaskInstance: weather_dag.extraction_weather_data manual__2023-03-30T02:36:00.079532+00:00 [queued]>
[2023-03-29 23:36:04,192] {taskinstance.py:1356} INFO - 
--------------------------------------------------------------------------------
[2023-03-29 23:36:04,192] {taskinstance.py:1357} INFO - Starting attempt 1 of 1
[2023-03-29 23:36:04,192] {taskinstance.py:1358} INFO - 
--------------------------------------------------------------------------------
[2023-03-29 23:36:04,197] {taskinstance.py:1377} INFO - Executing <Task(PythonOperator): extraction_weather_data> on 2023-03-30 02:36:00.079532+00:00
[2023-03-29 23:36:04,202] {standard_task_runner.py:52} INFO - Started process 13300 to run task
[2023-03-29 23:36:04,205] {standard_task_runner.py:79} INFO - Running: ['airflow', 'tasks', 'run', 'weather_dag', 'extraction_weather_data', 'manual__2023-03-30T02:36:00.079532+00:00', '--job-id', '67', '--raw', '--subdir', 'DAGS_FOLDER/weather_dag.py', '--cfg-path', '/var/folders/1t/ncp0s87s3bd37gfvks3bsb3w0000gn/T/tmpylydf7i5', '--error-file', '/var/folders/1t/ncp0s87s3bd37gfvks3bsb3w0000gn/T/tmpbkov0i7e']
[2023-03-29 23:36:04,206] {standard_task_runner.py:80} INFO - Job 67: Subtask extraction_weather_data
[2023-03-29 23:36:04,228] {task_command.py:370} INFO - Running <TaskInstance: weather_dag.extraction_weather_data manual__2023-03-30T02:36:00.079532+00:00 [running]> on host MacBook-Air-de-Gabriel.local
[2023-03-29 23:36:04,259] {taskinstance.py:1569} INFO - Exporting the following env vars:
AIRFLOW_CTX_DAG_OWNER=airflow
AIRFLOW_CTX_DAG_ID=weather_dag
AIRFLOW_CTX_TASK_ID=extraction_weather_data
AIRFLOW_CTX_EXECUTION_DATE=2023-03-30T02:36:00.079532+00:00
AIRFLOW_CTX_TRY_NUMBER=1
AIRFLOW_CTX_DAG_RUN_ID=manual__2023-03-30T02:36:00.079532+00:00
[2023-03-29 23:36:05,190] {taskinstance.py:1889} ERROR - Task failed with exception
Traceback (most recent call last):
  File "/Users/gabrielroger/Documents/projects/weather-data/.venv/lib/python3.9/site-packages/airflow/operators/python.py", line 171, in execute
    return_value = self.execute_callable()
  File "/Users/gabrielroger/Documents/projects/weather-data/.venv/lib/python3.9/site-packages/airflow/operators/python.py", line 189, in execute_callable
    return self.python_callable(*self.op_args, **self.op_kwargs)
  File "/Users/gabrielroger/Documents/projects/weather-data/dags/weather_dag.py", line 35, in extraction
    data[['datetime', 'tempmin', 'temp', 'tempax']].to_csv(file_path + 'temperature.csv')
  File "/Users/gabrielroger/Documents/projects/weather-data/.venv/lib/python3.9/site-packages/pandas/core/frame.py", line 3813, in __getitem__
    indexer = self.columns._get_indexer_strict(key, "columns")[1]
  File "/Users/gabrielroger/Documents/projects/weather-data/.venv/lib/python3.9/site-packages/pandas/core/indexes/base.py", line 6070, in _get_indexer_strict
    self._raise_if_missing(keyarr, indexer, axis_name)
  File "/Users/gabrielroger/Documents/projects/weather-data/.venv/lib/python3.9/site-packages/pandas/core/indexes/base.py", line 6133, in _raise_if_missing
    raise KeyError(f"{not_found} not in index")
KeyError: "['tempax'] not in index"
[2023-03-29 23:36:05,201] {taskinstance.py:1395} INFO - Marking task as FAILED. dag_id=weather_dag, task_id=extraction_weather_data, execution_date=20230330T023600, start_date=20230330T023604, end_date=20230330T023605
[2023-03-29 23:36:05,207] {standard_task_runner.py:92} ERROR - Failed to execute job 67 for task extraction_weather_data ("['tempax'] not in index"; 13300)
[2023-03-29 23:36:05,236] {local_task_job.py:156} INFO - Task exited with return code 1
[2023-03-29 23:36:05,252] {local_task_job.py:273} INFO - 0 downstream tasks scheduled from follow-on schedule check
