[2023-03-29 23:13:49,670] {taskinstance.py:1159} INFO - Dependencies all met for <TaskInstance: weather_dag.extraction_weather_data scheduled__2023-03-20T00:00:00+00:00 [queued]>
[2023-03-29 23:13:49,673] {taskinstance.py:1159} INFO - Dependencies all met for <TaskInstance: weather_dag.extraction_weather_data scheduled__2023-03-20T00:00:00+00:00 [queued]>
[2023-03-29 23:13:49,673] {taskinstance.py:1356} INFO - 
--------------------------------------------------------------------------------
[2023-03-29 23:13:49,673] {taskinstance.py:1357} INFO - Starting attempt 1 of 1
[2023-03-29 23:13:49,673] {taskinstance.py:1358} INFO - 
--------------------------------------------------------------------------------
[2023-03-29 23:13:49,679] {taskinstance.py:1377} INFO - Executing <Task(PythonOperator): extraction_weather_data> on 2023-03-20 00:00:00+00:00
[2023-03-29 23:13:49,684] {standard_task_runner.py:52} INFO - Started process 10974 to run task
[2023-03-29 23:13:49,688] {standard_task_runner.py:79} INFO - Running: ['airflow', 'tasks', 'run', 'weather_dag', 'extraction_weather_data', 'scheduled__2023-03-20T00:00:00+00:00', '--job-id', '47', '--raw', '--subdir', 'DAGS_FOLDER/weather_dag.py', '--cfg-path', '/var/folders/1t/ncp0s87s3bd37gfvks3bsb3w0000gn/T/tmphf4kn4n_', '--error-file', '/var/folders/1t/ncp0s87s3bd37gfvks3bsb3w0000gn/T/tmpyl3k_b_8']
[2023-03-29 23:13:49,689] {standard_task_runner.py:80} INFO - Job 47: Subtask extraction_weather_data
[2023-03-29 23:13:49,712] {task_command.py:370} INFO - Running <TaskInstance: weather_dag.extraction_weather_data scheduled__2023-03-20T00:00:00+00:00 [running]> on host 1.0.0.127.in-addr.arpa
[2023-03-29 23:13:49,737] {taskinstance.py:1569} INFO - Exporting the following env vars:
AIRFLOW_CTX_DAG_OWNER=airflow
AIRFLOW_CTX_DAG_ID=weather_dag
AIRFLOW_CTX_TASK_ID=extraction_weather_data
AIRFLOW_CTX_EXECUTION_DATE=2023-03-20T00:00:00+00:00
AIRFLOW_CTX_TRY_NUMBER=1
AIRFLOW_CTX_DAG_RUN_ID=scheduled__2023-03-20T00:00:00+00:00
[2023-03-29 23:13:49,738] {taskinstance.py:1889} ERROR - Task failed with exception
Traceback (most recent call last):
  File "/Users/gabrielroger/Documents/projects/weather-data/.venv/lib/python3.9/site-packages/airflow/operators/python.py", line 171, in execute
    return_value = self.execute_callable()
  File "/Users/gabrielroger/Documents/projects/weather-data/.venv/lib/python3.9/site-packages/airflow/operators/python.py", line 189, in execute_callable
    return self.python_callable(*self.op_args, **self.op_kwargs)
  File "/Users/gabrielroger/Documents/projects/weather-data/dags/weather_dag.py", line 29, in extraction
    f'{city}/{data_interval_end}/{ds_add(data_interval_end, 7)}?unitGroup=metric&include=days&key={key}&contentType=csv')
NameError: name 'data_interval_end' is not defined
[2023-03-29 23:13:49,741] {taskinstance.py:1395} INFO - Marking task as FAILED. dag_id=weather_dag, task_id=extraction_weather_data, execution_date=20230320T000000, start_date=20230330T021349, end_date=20230330T021349
[2023-03-29 23:13:49,744] {standard_task_runner.py:92} ERROR - Failed to execute job 47 for task extraction_weather_data (name 'data_interval_end' is not defined; 10974)
[2023-03-29 23:13:49,750] {local_task_job.py:156} INFO - Task exited with return code 1
[2023-03-29 23:13:49,760] {local_task_job.py:273} INFO - 0 downstream tasks scheduled from follow-on schedule check
