[2023-03-29 23:23:35,703] {taskinstance.py:1159} INFO - Dependencies all met for <TaskInstance: weather_dag.extraction_weather_data manual__2023-03-30T02:23:31.102141+00:00 [queued]>
[2023-03-29 23:23:35,706] {taskinstance.py:1159} INFO - Dependencies all met for <TaskInstance: weather_dag.extraction_weather_data manual__2023-03-30T02:23:31.102141+00:00 [queued]>
[2023-03-29 23:23:35,706] {taskinstance.py:1356} INFO - 
--------------------------------------------------------------------------------
[2023-03-29 23:23:35,706] {taskinstance.py:1357} INFO - Starting attempt 1 of 1
[2023-03-29 23:23:35,706] {taskinstance.py:1358} INFO - 
--------------------------------------------------------------------------------
[2023-03-29 23:23:35,711] {taskinstance.py:1377} INFO - Executing <Task(PythonOperator): extraction_weather_data> on 2023-03-30 02:23:31.102141+00:00
[2023-03-29 23:23:35,716] {standard_task_runner.py:52} INFO - Started process 11993 to run task
[2023-03-29 23:23:35,720] {standard_task_runner.py:79} INFO - Running: ['airflow', 'tasks', 'run', 'weather_dag', 'extraction_weather_data', 'manual__2023-03-30T02:23:31.102141+00:00', '--job-id', '59', '--raw', '--subdir', 'DAGS_FOLDER/weather_dag.py', '--cfg-path', '/var/folders/1t/ncp0s87s3bd37gfvks3bsb3w0000gn/T/tmpt1vb7ook', '--error-file', '/var/folders/1t/ncp0s87s3bd37gfvks3bsb3w0000gn/T/tmp8jvroyl7']
[2023-03-29 23:23:35,721] {standard_task_runner.py:80} INFO - Job 59: Subtask extraction_weather_data
[2023-03-29 23:23:35,745] {task_command.py:370} INFO - Running <TaskInstance: weather_dag.extraction_weather_data manual__2023-03-30T02:23:31.102141+00:00 [running]> on host MacBook-Air-de-Gabriel.local
[2023-03-29 23:23:35,768] {taskinstance.py:1569} INFO - Exporting the following env vars:
AIRFLOW_CTX_DAG_OWNER=airflow
AIRFLOW_CTX_DAG_ID=weather_dag
AIRFLOW_CTX_TASK_ID=extraction_weather_data
AIRFLOW_CTX_EXECUTION_DATE=2023-03-30T02:23:31.102141+00:00
AIRFLOW_CTX_TRY_NUMBER=1
AIRFLOW_CTX_DAG_RUN_ID=manual__2023-03-30T02:23:31.102141+00:00
[2023-03-29 23:23:36,547] {taskinstance.py:1889} ERROR - Task failed with exception
Traceback (most recent call last):
  File "/Users/gabrielroger/Documents/projects/weather-data/.venv/lib/python3.9/site-packages/airflow/operators/python.py", line 171, in execute
    return_value = self.execute_callable()
  File "/Users/gabrielroger/Documents/projects/weather-data/.venv/lib/python3.9/site-packages/airflow/operators/python.py", line 189, in execute_callable
    return self.python_callable(*self.op_args, **self.op_kwargs)
  File "/Users/gabrielroger/Documents/projects/weather-data/dags/weather_dag.py", line 35, in extraction
    os.mkdir(file_path)
FileExistsError: [Errno 17] File exists: '/Users/gabrielroger/Documents/projects/weather-data/week=2023-03-27/'
[2023-03-29 23:23:36,554] {taskinstance.py:1395} INFO - Marking task as FAILED. dag_id=weather_dag, task_id=extraction_weather_data, execution_date=20230330T022331, start_date=20230330T022335, end_date=20230330T022336
[2023-03-29 23:23:36,562] {standard_task_runner.py:92} ERROR - Failed to execute job 59 for task extraction_weather_data ([Errno 17] File exists: '/Users/gabrielroger/Documents/projects/weather-data/week=2023-03-27/'; 11993)
[2023-03-29 23:23:36,613] {local_task_job.py:156} INFO - Task exited with return code 1
[2023-03-29 23:23:36,638] {local_task_job.py:273} INFO - 0 downstream tasks scheduled from follow-on schedule check
